<?xml version="1.0"?>
<robot xmlns:xacro="http://ros.org/wiki/xacro">

    <xacro:macro name="standard_jaws"
        params="parent prefix description_package axis_a *origin">

        <!-- Material for jaws -->
        <material name="${prefix}_black">
            <color rgba="0.3 0.3 0.3 1" />
        </material>

        <!-- Base link of the jaws -->
        <link name="${prefix}base_link">
            <visual>
                <geometry>
                    <mesh filename="package://${description_package}/meshes/end_effectors/RS1-124.stl" />
                </geometry>
                <material name="${prefix}_black" />
            </visual>
        </link>

        <!-- First jaw link -->
        <link name="${prefix}rs1_130_link">
            <visual>
                <geometry>
                    <mesh filename="package://${description_package}/meshes/end_effectors/RS1-130.stl" />
                </geometry>
                <material name="${prefix}_black" />
            </visual>
        </link>

        <joint name="${prefix}rs1_130_joint" type="revolute">
            <origin xyz="0 0.0155 0.0069" rpy="0 0 0" />
            <parent link="${prefix}base_link" />
            <child link="${prefix}rs1_130_link" />
            <axis xyz="-1 0 0" />
            <limit lower="0" upper="0.5" effort="10" velocity="10" />
            <mimic joint="${axis_a}" multiplier="51" offset="0" />
        </joint>

        <!-- Second jaw link -->
        <link name="${prefix}rs1_139_link">
            <visual>
                <geometry>
                    <mesh filename="package://${description_package}/meshes/end_effectors/RS1-139.stl" />
                </geometry>
                <material name="${prefix}_black" />
            </visual>
        </link>

        <joint name="${prefix}rs1_139_joint" type="revolute">
            <origin xyz="0 -0.0155 0.0069" rpy="0 0 0" />
            <parent link="${prefix}base_link" />
            <child link="${prefix}rs1_139_link" />
            <axis xyz="1 0 0" />
            <limit lower="0" upper="0.5" effort="10" velocity="10" />
            <mimic joint="${prefix}rs1_130_joint" multiplier="1" offset="0" />
        </joint>

        <!-- Tool attachment point -->
        <link name="${prefix}tool">
            <inertial>
                <mass value="0.0001" />
                <inertia
                    ixx="0.0001"
                    ixy="0"
                    ixz="0"
                    iyy="0.0001"
                    iyz="0"
                    izz="0.0001"
                />
            </inertial>
        </link>

        <joint name="${prefix}tool_joint" type="fixed">
            <origin xyz="0 0 0.04" rpy="0 -1.571 0" />
            <parent link="${prefix}base_link" />
            <child link="${prefix}tool" />
        </joint>

    </xacro:macro>

</robot>
