<?xml version="1.0" ?>
<!-- =================================================================================== -->
<!-- |    This document was autogenerated by xacro from alpha.config.xacro             | -->
<!-- |    EDITING THIS FILE BY HAND IS NOT RECOMMENDED                                 | -->
<!-- =================================================================================== -->
<robot name="alpha">
  <link name="base_footprint"/>
  <material name="black">
    <color rgba="0.3 0.3 0.3 1"/>
  </material>
  <link name="base_link">
    <visual>
      <origin rpy="0 0 0" xyz="0 0 0"/>
      <geometry>
        <box size="0.001 0.001 0.001"/>
      </geometry>
    </visual>
    <inertial>
      <mass value="0.0001"/>
      <inertia ixx="0.0001" ixy="0" ixz="0" iyy="0.0001" iyz="0" izz="0.0001"/>
    </inertial>
  </link>
  <link name="m3_inline_link">
    <visual>
      <geometry>
        <mesh filename="meshes/M3-INLINE.stl"/>
      </geometry>
      <origin rpy="0 0 0" xyz="0 0 0"/>
      <material name="black"/>
    </visual>
    <collision>
      <geometry>
        <cylinder length="0.150" radius="0.020"/>
      </geometry>
      <origin rpy="0 1.57075 0" xyz="-0.055 0 0"/>
    </collision>
    <inertial>
      <mass value="0.341"/>
      <origin xyz="-0.055 0 0"/>
      <inertia ixx="0.0000682" ixy="0" ixz="0" iyy="0.000673" iyz="0" izz="0.000673"/>
    </inertial>
  </link>
  <link name="m2_1_1_link">
    <visual>
      <geometry>
        <mesh filename="meshes/M2-1-1.stl"/>
      </geometry>
      <origin rpy="0 0 0" xyz="0 0 0"/>
      <material name="black"/>
    </visual>
    <collision>
      <geometry>
        <cylinder length="0.033" radius="0.020"/>
      </geometry>
      <origin rpy="0 0 0" xyz="0 0 0.0165"/>
    </collision>
    <inertial>
      <mass value="0.194"/>
      <origin xyz="0 0 0.0165"/>
      <inertia ixx="0.000037" ixy="0" ixz="0" iyy="0.000037" iyz="0" izz="0.0000388"/>
    </inertial>
  </link>
  <link name="m2_joint_link">
    <visual>
      <geometry>
        <mesh filename="meshes/M2.stl"/>
      </geometry>
      <origin rpy="0 0 0" xyz="0 0 0"/>
      <material name="black"/>
    </visual>
    <collision>
      <geometry>
        <cylinder length="0.145" radius="0.020"/>
      </geometry>
      <origin rpy="0 0 0" xyz="-0.02 0 -0.0725"/>
    </collision>
    <collision>
      <geometry>
        <cylinder length="0.040" radius="0.020"/>
      </geometry>
      <origin rpy="1.5707 0 0" xyz="0 0 0"/>
    </collision>
    <collision>
      <geometry>
        <cylinder length="0.040" radius="0.020"/>
      </geometry>
      <origin rpy="1.5707 0 0" xyz="-0.040 0 -0.1453"/>
    </collision>
    <inertial>
      <mass value="0.429"/>
      <origin xyz="-0.02 0 -0.0725"/>
      <inertia ixx="0.0008907" ixy="0" ixz="0" iyy="0.0008907" iyz="0" izz="0.0000858"/>
    </inertial>
  </link>
  <link name="m2_1_2_link">
    <visual>
      <geometry>
        <mesh filename="meshes/M2-1-3.stl"/>
      </geometry>
      <origin rpy="0 0 0" xyz="0 0 0"/>
      <material name="black"/>
    </visual>
    <collision>
      <geometry>
        <cylinder length="0.033" radius="0.020"/>
      </geometry>
      <origin rpy="0 0 0" xyz="0.02 0 0.0165"/>
    </collision>
    <inertial>
      <mass value="0.115"/>
      <origin xyz="0.02 0 0.0165"/>
      <inertia ixx="0.0000219" ixy="0" ixz="0" iyy="0.0000219" iyz="0" izz="0.000023"/>
    </inertial>
  </link>
  <link name="m1_link">
    <visual>
      <geometry>
        <mesh filename="meshes/RS1-100-101-123.stl"/>
      </geometry>
      <origin rpy="0 -1.5707 0" xyz="0 0 0"/>
      <material name="black"/>
    </visual>
    <collision>
      <geometry>
        <cylinder length="0.1" radius="0.020"/>
      </geometry>
      <origin rpy="0 0 0" xyz="0 0 0.05"/>
    </collision>
    <inertial>
      <mass value="0.200"/>
      <origin xyz="0 0 0.05"/>
      <inertia ixx="0.0001867" ixy="0" ixz="0" iyy="0.0001867" iyz="0" izz="0.00004"/>
    </inertial>
  </link>
  <link name="ee_base_link">
    <visual>
      <origin rpy="0 0 0" xyz="0 0 0"/>
      <geometry>
        <box size="0.001 0.001 0.001"/>
      </geometry>
    </visual>
    <inertial>
      <mass value="0.0001"/>
      <inertia ixx="0.0001" ixy="0" ixz="0" iyy="0.0001" iyz="0" izz="0.0001"/>
    </inertial>
  </link>
  <link name="push_rod">
    <visual>
      <origin rpy="0 0 0" xyz="0 0 0"/>
      <geometry>
        <box size="0.001 0.001 0.001"/>
      </geometry>
    </visual>
    <inertial>
      <mass value="0.0001"/>
      <inertia ixx="0.0001" ixy="0" ixz="0" iyy="0.0001" iyz="0" izz="0.0001"/>
    </inertial>
  </link>
  <joint name="base_joint" type="fixed">
    <origin rpy="0 0 0" xyz="0 0 0"/>
    <parent link="base_footprint"/>
    <child link="base_link"/>
  </joint>
  <joint name="base_link_joint" type="fixed">
    <parent link="base_link"/>
    <child link="m3_inline_link"/>
    <origin rpy="0 0 0"/>
  </joint>
  <joint name="axis_e" type="revolute">
    <parent link="m3_inline_link"/>
    <child link="m2_1_1_link"/>
    <origin xyz="0 0 0.014"/>
    <axis xyz="0 0 1"/>
    <limit effort="9.0" lower="0.0" upper="6.10" velocity="0.5"/>
  </joint>
  <joint name="axis_d" type="revolute">
    <parent link="m2_1_1_link"/>
    <child link="m2_joint_link"/>
    <origin xyz="-0.02 0 0.033"/>
    <axis xyz="0 1 0"/>
    <!-- The true lower limit is 0.0; however, this breaks for some reason with ros2_control -->
    <limit effort="9.0" lower="-3.49" upper="3.49" velocity="0.5"/>
  </joint>
  <joint name="axis_c" type="revolute">
    <parent link="m2_joint_link"/>
    <child link="m2_1_2_link"/>
    <origin rpy="0 0 3.14159" xyz="-0.04 0 -0.1453"/>
    <axis xyz="0 1 0"/>
    <limit effort="9.0" lower="0.0" upper="3.22" velocity="0.5"/>
  </joint>
  <joint name="axis_b" type="revolute">
    <parent link="m2_1_2_link"/>
    <child link="m1_link"/>
    <origin rpy="0 0 2.09439" xyz="0.02 0 0.033"/>
    <axis xyz="0 0 -1"/>
    <limit effort="9.0" lower="0.0" upper="3.22" velocity="0.5"/>
  </joint>
  <joint name="ee_joint" type="fixed">
    <origin rpy="0 0 0" xyz="0 0 0.09975"/>
    <parent link="m1_link"/>
    <child link="ee_base_link"/>
  </joint>
  <joint name="axis_a" type="prismatic">
    <origin rpy="0 0 0" xyz="0 0 0.009"/>
    <parent link="ee_base_link"/>
    <child link="push_rod"/>
    <axis xyz="0 0 1"/>
    <limit effort="10" lower="0" upper="0.015" velocity="10"/>
  </joint>
  <material name="standard_jaws_black">
    <color rgba="0.3 0.3 0.3 1"/>
  </material>
  <link name="standard_jaws_base_link">
    <visual>
      <geometry>
        <mesh filename="meshes/end_effectors/RS1-124.stl"/>
      </geometry>
      <material name="standard_jaws_black"/>
    </visual>
    <collision>
      <geometry>
        <cylinder length="0.00975" radius="0.020"/>
      </geometry>
      <origin rpy="0 0 0" xyz="0 0 0.004875"/>
    </collision>
    <inertial>
      <mass value="0.023"/>
      <origin xyz="0 0 0.004875"/>
      <inertia ixx="0.000002422" ixy="0" ixz="0" iyy="0.000002422" iyz="0" izz="0.0000046"/>
    </inertial>
  </link>
  <link name="standard_jaws_rs1_130_link">
    <visual>
      <geometry>
        <mesh filename="meshes/end_effectors/RS1-130.stl"/>
      </geometry>
      <material name="standard_jaws_black"/>
      <origin rpy="0 0 0" xyz="0 0 0"/>
    </visual>
    <collision>
      <geometry>
        <box size="0.012 0.03 0.09"/>
      </geometry>
      <origin rpy="0 0 0" xyz="0.0 -0.008 0.045"/>
    </collision>
    <inertial>
      <mass value="0.055"/>
      <origin rpy="0 0 0" xyz="0.0 -0.008 0.045"/>
      <inertia ixx="0.00004125" ixy="0" ixz="0" iyy="0.000037785" iyz="0" izz="0.000004785"/>
    </inertial>
  </link>
  <link name="standard_jaws_rs1_139_link">
    <visual>
      <geometry>
        <mesh filename="meshes/end_effectors/RS1-139.stl"/>
      </geometry>
      <material name="standard_jaws_black"/>
      <origin rpy="0 0 0" xyz="0 0 0"/>
    </visual>
    <collision>
      <geometry>
        <box size="0.012 0.03 0.09"/>
      </geometry>
      <origin rpy="0 0 0" xyz="0.0 0.008 0.045"/>
    </collision>
    <inertial>
      <mass value="0.055"/>
      <origin rpy="0 0 0" xyz="0.0 0.008 0.045"/>
      <inertia ixx="0.00004125" ixy="0" ixz="0" iyy="0.000037785" iyz="0" izz="0.000004785"/>
    </inertial>
  </link>
  <link name="standard_jaws_tool">
    <inertial>
      <mass value="0.0001"/>
      <inertia ixx="0.0001" ixy="0" ixz="0" iyy="0.0001" iyz="0" izz="0.0001"/>
    </inertial>
  </link>
  <joint name="standard_jaws_base_joint" type="fixed">
    <origin rpy="0 0 0" xyz="0 0 0"/>
    <parent link="ee_base_link"/>
    <child link="standard_jaws_base_link"/>
    <origin rpy="0 0 0" xyz="0 0 0"/>
  </joint>
  <joint name="standard_jaws_rs1_130_joint" type="revolute">
    <origin rpy="0 0 0" xyz="0 0.0155 0.0069"/>
    <parent link="standard_jaws_base_link"/>
    <child link="standard_jaws_rs1_130_link"/>
    <axis xyz="-1 0 0"/>
    <limit effort="10" lower="0" upper="0.5" velocity="10"/>
    <mimic joint="axis_a" multiplier="51" offset="0"/>
  </joint>
  <joint name="standard_jaws_rs1_139_joint" type="revolute">
    <origin rpy="0 0 0" xyz="0 -0.0155 0.0069"/>
    <parent link="standard_jaws_base_link"/>
    <child link="standard_jaws_rs1_139_link"/>
    <axis xyz="1 0 0"/>
    <limit effort="10" lower="0" upper="0.5" velocity="10"/>
    <mimic joint="standard_jaws_rs1_130_joint" multiplier="1" offset="0"/>
  </joint>
  <joint name="standard_jaws_tool_joint" type="fixed">
    <origin rpy="0 -1.571 0" xyz="0 0 0.04"/>
    <parent link="standard_jaws_base_link"/>
    <child link="standard_jaws_tool"/>
  </joint>
  <ros2_control name="ReachAlpha5" type="system">
    <hardware>
      <plugin>mock_components/GenericSystem</plugin>
    </hardware>
    <joint name="axis_a">
      <command_interface name="position">
        <param name="min">0</param>
        <param name="max">0.015</param>
      </command_interface>
      <command_interface name="velocity">
        <param name="min">-2.5</param>
        <param name="max">2.5</param>
      </command_interface>
      <state_interface name="position">
        <param name="initial_value">0</param>
      </state_interface>
      <state_interface name="velocity">
        <param name="initial_value">0.0</param>
      </state_interface>
    </joint>
    <joint name="axis_b">
      <command_interface name="position">
        <param name="min">0</param>
        <param name="max">3.22</param>
      </command_interface>
      <command_interface name="velocity">
        <param name="min">-1.0</param>
        <param name="max">1.0</param>
      </command_interface>
      <state_interface name="position">
        <param name="initial_value">0</param>
      </state_interface>
      <state_interface name="velocity">
        <param name="initial_value">0.0</param>
      </state_interface>
    </joint>
    <joint name="axis_c">
      <command_interface name="position">
        <param name="min">0</param>
        <param name="max">3.22</param>
      </command_interface>
      <command_interface name="velocity">
        <param name="min">-1.0</param>
        <param name="max">1.0</param>
      </command_interface>
      <state_interface name="position">
        <param name="initial_value">0</param>
      </state_interface>
      <state_interface name="velocity">
        <param name="initial_value">0.0</param>
      </state_interface>
    </joint>
    <joint name="axis_d">
      <command_interface name="position">
        <param name="min">0</param>
        <param name="max">3.49</param>
      </command_interface>
      <command_interface name="velocity">
        <param name="min">-1.0</param>
        <param name="max">1.0</param>
      </command_interface>
      <state_interface name="position">
        <param name="initial_value">1.5746</param>
      </state_interface>
      <state_interface name="velocity">
        <param name="initial_value">0.0</param>
      </state_interface>
    </joint>
    <joint name="axis_e">
      <command_interface name="position">
        <param name="min">0</param>
        <param name="max">6.10</param>
      </command_interface>
      <command_interface name="velocity">
        <param name="min">-0.5</param>
        <param name="max">0.5</param>
      </command_interface>
      <state_interface name="position">
        <param name="initial_value">0</param>
      </state_interface>
      <state_interface name="velocity">
        <param name="initial_value">0.0</param>
      </state_interface>
    </joint>
  </ros2_control>
</robot>
